<mujoco>
  <compiler autolimits="true"/>

  <asset>
    <texture name="grid" type="2d" builtin="checker" width="512" height="512" rgb1=".1 .2 .3" rgb2=".2 .3 .4"/>
    <material name="grid" texture="grid" texrepeat="1 1" texuniform="true" reflectance=".2"/>
  </asset>

  <default>
    <joint damping=".03" actuatorfrcrange="-0.5 0.5"/>
    <default class="wheel">
      <geom type="sphere" size=".03" rgba=".5 .5 1 1"/>
    </default>
    <default class="decor">
      <site type="box" rgba=".5 1 .5 1"/>
    </default>
  </default>

  <worldbody>
    <geom type="plane" size="3 3 .01" material="grid"/>
    <body name="car" pos="0 0 .03">
      <freejoint/>
      <light name="top light" pos="0 0 2" mode="trackcom" diffuse=".4 .4 .4"/>
      <geom name="chasis" type="box" size=".1 .05 .02"/>
      <geom name="front wheel" pos=".08 0 -.015" type="sphere" size=".015" condim="1" priority="1"/>
      <light name="front light" pos=".1 0 .02" dir="2 0 -1" diffuse="1 1 1"/>
      <camera name="front_camera" pos=".1 0 .02" xyaxes="0 -1 0 0 0 1" fovy="90"/>
      <body name="left wheel" pos="-.07 .06 0" zaxis="0 1 0">
        <joint name="left"/>
        <geom class="wheel"/>
        <site class="decor" size=".006 .025 .012"/>
        <site class="decor" size=".025 .006 .012"/>
      </body>
      <body name="right wheel" pos="-.07 -.06 0" zaxis="0 1 0">
        <joint name="right"/>
        <geom class="wheel"/>
        <site class="decor" size=".006 .025 .012"/>
        <site class="decor" size=".025 .006 .012"/>
      </body>
    </body>
    <body name="red_cube" pos="2.9 2.9 0.05">
      <geom type="box" size=".05 .05 .05" rgba="1 0 0 1"/>
    </body>
  </worldbody>

  <actuator>
      <motor name="drive_left" joint="left" ctrlrange="-1 1"/>
      <motor name="drive_right" joint="right" ctrlrange="-1 1"/>
  </actuator>

  <sensor>
    <jointactuatorfrc name="right" joint="right"/>
    <jointactuatorfrc name="left" joint="left"/>
  </sensor>
</mujoco>